Workbook

Sheet Parametros
A1: Parametros de balanceamento - Jogo de Cartas Minerais v2
A2: Base: Resolucao CTAPME no 2, de 18/06/2021. Celulas AZUIS sao os botoes de ajuste.
A4: Parametro | B4: Valor | C4: Observacao
A5: Ataque - deslocamento (log10 do preco) | B5: 2 | C5: Preco de referencia equivalente a ataque 1
A6: Ataque - fator de escala | B6: 1.5 | C6: Ataque ganho por decada de preco
A7: Ataque - minimo | B7: 1
A8: Ataque - maximo | B8: 9
A9: Custo - multiplicador Bloco I | B9: 1.15 | C9: Dependencia de importacao encarece
A10: Custo - multiplicador Bloco II | B10: 1 | C10: Referencia
A11: Custo - multiplicador Bloco III | B11: 0.8 | C11: Vantagem comparativa barateia
A12: Custo - minimo | B12: 1
A13: Custo - maximo | B13: 9
A14: Copias no pool - Bloco I | B14: 2 | C14: Escassez real vira escassez no baralho
A15: Copias no pool - Bloco II | B15: 3
A16: Copias no pool - Bloco III | B16: 4
A17: Reserva (vida) inicial | B17: 15 | C17: Vida do heroi. Sobe se a partida estiver curta demais.
A18: Tamanho do baralho por jogador | B18: 18 | C18: Sorteado do pool. Tem que durar a partida, senao a exaustao decide.
A19: Mao inicial | B19: 3 | C19: Quem joga em segundo compra mais (ver abaixo)
A22: Formulas
A23: Defesa = dureza Mohs do mineral de referencia, arredondada
A24: Ataque = ARRED((LOG10(preco) - deslocamento) * fator + 1) , limitado entre min e max
A25: Custo = ARRED((Ataque + Defesa)/2 * multiplicador do bloco) , limitado entre min e max
A27: REGRA DA DUREZA
A28: A Resolucao lista SUBSTANCIAS (mistura elemento e minerio). A carta segue a substancia.
A29: A dureza vem do MINERAL DE REFERENCIA: o mineral-minerio predominantemente lavrado no Brasil.
A30: A coluna 'Mineral de referencia' declara essa escolha carta a carta - e o que torna o dado auditavel.
A32: FONTES
A33: Blocos: Resolucao CTAPME no 2/2021 (MME) - transcrita da lista oficial fornecida pelo usuario.
A34: Dureza Mohs: tabela mineralogica padrao; onde ha intervalo, ponto medio.
A35: Precos: ordens de grandeza ILUSTRATIVAS em US$/t, para calibrar o jogo - NAO sao cotacao.
... A41: Editar AQUI. O motor so usa o proprio padrao se a linha sumir daqui.
A43: chave | B43: valor | C43: observacao
A44: maoSegundo | B44: 5 | C44: Mao inicial de quem joga em segundo
A45: baralhoSegundoExtra | B45: 2 | C45: Cartas a mais no baralho dele: a mao maior sai de dentro do baralho
A46: fichaSegundo1 | B46: 2 | C46: Energia extra no 1o turno dele
A47: fichaSegundo2 | B47: 1 | C47: Energia extra no 2o turno dele (meia ficha: 2 sozinho da 57%, 3 da 37%)
A48: energiaInicial | B48: 2
A49: energiaMax | B49: 9
A50: campoMax | B50: 3 | C50: Vagas no campo
A51: maoMax | B51: 8 | C51: Acima disso nao compra
...

Sheet Cartas
A1: Cartas - 23 substancias oficiais + 2 complementares
A2: Azul = voce edita. Preto = calculado, nao digite por cima.
R3: Ajuste manual por carta (eixo de liga). Soma ao valor do bloco.
A4: # | B4: Carta (substancia) | C4: Bloco | D4: Tambem no bloco | E4: Oficial? | F4: Classe (cor) | G4: Mineral de referencia (BR) | H4: Formula | I4: Elemento | J4: Mohs | K4: Preco ref. (US$/t) | L4: Base do preco | M4: ATAQUE | N4: DEFESA | O4: CUSTO | P4: Copias | Q4: Nota | R4: Copias extra
A5: 1 | B5: Enxofre | C5: I | E5: Sim | F5: Vermelho - Dependencia | G5: Enxofre nativo | H5: S | I5: S | J5: 2 | K5: 100 | L5: Enxofre bruto | M5: =MIN(Parametros!$B$8,MAX(Parametros!$B$7,ROUND((LOG10(K5)-Parametros!$B$5)*Parametros!$B$6+1,0))) -> 1 | N5: =ROUND(J5,0) -> 2 | O5: =MIN(Parametros!$B$13,MAX(Parametros!$B$12,ROUND((M5+N5)/2*IF(C5="I",Parametros!$B$9,IF(C5="II",Parametros!$B$10,Parametros!$B$11)),0))) -> 2 | P5: =IF(C5="I",Parametros!$B$14,IF(C5="II",Parametros!$B$15,Parametros!$B$16)) -> 2 | R5: 0
A6: 2 | B6: Minerio de Fosfato | C6: I | E6: Sim | F6: Vermelho - Dependencia | G6: Apatita | H6: Ca5(PO4)3(F,OH) | I6: P | J6: 5 | K6: 300 | L6: Concentrado fosfatico | M6: =MIN(Parametros!$B$8,MAX(Parametros!$B$7,ROUND((LOG10(K6)-Parametros!$B$5)*Parametros!$B$6+1,0))) -> 2 | N6: =ROUND(J6,0) -> 5 | O6: =MIN(Parametros!$B$13,MAX(Parametros!$B$12,ROUND((M6+N6)/2*IF(C6="I",Parametros!$B$9,IF(C6="II",Parametros!$B$10,Parametros!$B$11)),0))) -> 4 | P6: =IF(C6="I",Parametros!$B$14,IF(C6="II",Parametros!$B$15,Parametros!$B$16)) -> 2 | R6: 0
A7: 3 | B7: Minerio de Potassio | C7: I | E7: Sim | F7: Vermelho - Dependencia | G7: Silvita | H7: KCl | I7: K | J7: 2 | K7: 320 | L7: Cloreto de potassio (KCl) | M7: =MIN(Parametros!$B$8,MAX(Parametros!$B$7,ROUND((LOG10(K7)-Parametros!$B$5)*Parametros!$B$6+1,0))) -> 2 | N7: =ROUND(J7,0) -> 2 | O7: =MIN(Parametros!$B$13,MAX(Parametros!$B$12,ROUND((M7+N7)/2*IF(C7="I",Parametros!$B$9,IF(C7="II",Parametros!$B$10,Parametros!$B$11)),0))) -> 2 | P7: =IF(C7="I",Parametros!$B$14,IF(C7="II",Parametros!$B$15,Parametros!$B$16)) -> 2 | R7: 0
A8: 4 | B8: Minerio de Molibdenio | C8: I | E8: Sim | F8: Vermelho - Dependencia | G8: Molibdenita | H8: MoS2 | I8: Mo | J8: 1.25 | K8: 40000 | L8: Molibdenio metalico | M8: =MIN(Parametros!$B$8,MAX(Parametros!$B$7,ROUND((LOG10(K8)-Parametros!$B$5)*Parametros!$B$6+1,0))) -> 5 | N8: =ROUND(J8,0) -> 1 | O8: =MIN(Parametros!$B$13,MAX(Parametros!$B$12,ROUND((M8+N8)/2*IF(C8="I",Parametros!$B$9,IF(C8="II",Parametros!$B$10,Parametros!$B$11)),0))) -> 3 | P8: =IF(C8="I",Parametros!$B$14,IF(C8="II",Parametros!$B$15,Parametros!$B$16)) -> 2 | Q8: Mohs 1-1,5: risca com a unha. Canhao de vidro. | R8: 0
A9: 5 | B9: Minerio de Cobalto | C9: II | E9: Sim | F9: Roxo - Tecnologia | G9: Asbolana (laterita niquelifera) | H9: (Mn,Co)O(OH)2.nH2O | I9: Co | J9: 2.5 | K9: 30000 | L9: Cobalto refinado | M9: =MIN(Parametros!$B$8,MAX(Parametros!$B$7,ROUND((LOG10(K9)-Parametros!$B$5)*Parametros!$B$6+1,0))) -> 5 | N9: =ROUND(J9,0) -> 3 | O9: =MIN(Parametros!$B$13,MAX(Parametros!$B$12,ROUND((M9+N9)/2*IF(C9="I",Parametros!$B$9,IF(C9="II",Parametros!$B$10,Parametros!$B$11)),0))) -> 4 | P9: =IF(C9="I",Parametros!$B$14,IF(C9="II",Parametros!$B$15,Parametros!$B$16)) -> 3 | Q9: So existe como SUBPRODUTO de niquel no Brasil - nao ha mina propria. Fase portadora na zona limonitica. | R9: 0
A10: 6 | B10: Minerio de Cobre | C10: II | D10: III | E10: Sim | F10: Roxo - Tecnologia | G10: Calcopirita | H10: CuFeS2 | I10: Cu | J10: 3.75 | K10: 9200 | L10: Cobre refinado | M10: =MIN(Parametros!$B$8,MAX(Parametros!$B$7,ROUND((LOG10(K10)-Parametros!$B$5)*Parametros!$B$6+1,0))) -> 4 | N10: =ROUND(J10,0) -> 4 | O10: =MIN(Parametros!$B$13,MAX(Parametros!$B$12,ROUND((M10+N10)/2*IF(C10="I",Parametros!$B$9,IF(C10="II",Parametros!$B$10,Parametros!$B$11)),0))) -> 4 | P10: =IF(C10="I",Parametros!$B$14,IF(C10="II",Parametros!$B$15,Parametros!$B$16)) -> 3 | Q10: Bloco duplo. | R10: 1
A11: 7 | B11: Minerio de Estanho | C11: II | E11: Sim | F11: Roxo - Tecnologia | G11: Cassiterita | H11: SnO2 | I11: Sn | J11: 6.5 | K11: 31000 | L11: Estanho refinado | M11: =MIN(Parametros!$B$8,MAX(Parametros!$B$7,ROUND((LOG10(K11)-Parametros!$B$5)*Parametros!$B$6+1,0))) -> 5 | N11: =ROUND(J11,0) -> 7 | O11: =MIN(Parametros!$B$13,MAX(Parametros!$B$12,ROUND((M11+N11)/2*IF(C11="I",Parametros!$B$9,IF(C11="II",Parametros!$B$10,Parametros!$B$11)),0))) -> 6 | P11: =IF(C11="I",Parametros!$B$14,IF(C11="II",Parametros!$B$15,Parametros!$B$16)) -> 3 | Q11: Pitinga (AM) e Bom Futuro (RO). | R11: 0
A12: 8 | B12: Minerio de Grafita | C12: II | D12: III | E12: Sim | F12: Roxo - Tecnologia | G12: Grafita | H12: C | I12: C | J12: 1.5 | K12: 650 | L12: Grafita natural em flocos | M12: =MIN(Parametros!$B$8,MAX(Parametros!$B$7,ROUND((LOG10(K12)-Parametros!$B$5)*Parametros!$B$6+1,0))) -> 2 | N12: =ROUND(J12,0) -> 2 | O12: =MIN(Parametros!$B$13,MAX(Parametros!$B$12,ROUND((M12+N12)/2*IF(C12="I",Parametros!$B$9,IF(C12="II",Parametros!$B$10,Parametros!$B$11)),0))) -> 2 | P12: =IF(C12="I",Parametros!$B$14,IF(C12="II",Parametros!$B$15,Parametros!$B$16)) -> 3 | Q12: Bloco duplo. | R12: 1
A13: 9 | B13: Minerios do grupo da platina | C13: II | E13: Sim | F13: Roxo - Tecnologia | G13: Esperrilita | H13: PtAs2 | I13: Pt, Pd | J13: 6.5 | K13: 32000000 | L13: Platina | M13: =MIN(Parametros!$B$8,MAX(Parametros!$B$7,ROUND((LOG10(K13)-Parametros!$B$5)*Parametros!$B$6+1,0))) -> 9 | N13: =ROUND(J13,0) -> 7 | O13: =MIN(Parametros!$B$13,MAX(Parametros!$B$12,ROUND((M13+N13)/2*IF(C13="I",Parametros!$B$9,IF(C13="II",Parametros!$B$10,Parametros!$B$11)),0))) -> 8 | P13: =IF(C13="I",Parametros!$B$14,IF(C13="II",Parametros!$B$15,Parametros!$B$16)) -> 3 | R13: 0
A14: 10 | B14: Minerio de Litio | C14: II | E14: Sim | F14: Roxo - Tecnologia | G14: Espodumenio | H14: LiAlSi2O6 | I14: Li | J14: 6.75 | K14: 12000 | L14: Carbonato de litio equiv. | M14: =MIN(Parametros!$B$8,MAX(Parametros!$B$7,ROUND((LOG10(K14)-Parametros!$B$5)*Parametros!$B$6+1,0))) -> 4 | N14: =ROUND(J14,0) -> 7 | O14: =MIN(Parametros!$B$13,MAX(Parametros!$B$12,ROUND((M14+N14)/2*IF(C14="I",Parametros!$B$9,IF(C14="II",Parametros!$B$10,Parametros!$B$11)),0))) -> 6 | P14: =IF(C14="I",Parametros!$B$14,IF(C14="II",Parametros!$B$15,Parametros!$B$16)) -> 3 | Q14: Vale do Jequitinhonha (MG). | R14: 0
A15: 11 | B15: Minerio de Niobio | C15: II | D15: III | E15: Sim | F15: Roxo - Tecnologia | G15: Pirocloro | H15: (Na,Ca)2Nb2O6(OH,F) | I15: Nb | J15: 5.25 | K15: 45000 | L15: Ferronióbio | M15: =MIN(Parametros!$B$8,MAX(Parametros!$B$7,ROUND((LOG10(K15)-Parametros!$B$5)*Parametros!$B$6+1,0))) -> 5 | N15: =ROUND(J15,0) -> 5 | O15: =MIN(Parametros!$B$13,MAX(Parametros!$B$12,ROUND((M15+N15)/2*IF(C15="I",Parametros!$B$9,IF(C15="II",Parametros!$B$10,Parametros!$B$11)),0))) -> 5 | P15: =IF(C15="I",Parametros!$B$14,IF(C15="II",Parametros!$B$15,Parametros!$B$16)) -> 3 | Q15: Bloco duplo. Brasil ~90% da oferta mundial. | R15: 0
A16: 12 | B16: Minerio de Niquel | C16: II | E16: Sim | F16: Roxo - Tecnologia | G16: Garnierita | H16: (Ni,Mg)3Si2O5(OH)4 | I16: Ni | J16: 3 | K16: 16000 | L16: Niquel refinado | M16: =MIN(Parametros!$B$8,MAX(Parametros!$B$7,ROUND((LOG10(K16)-Parametros!$B$5)*Parametros!$B$6+1,0))) -> 4 | N16: =ROUND(J16,0) -> 3 | O16: =MIN(Parametros!$B$13,MAX(Parametros!$B$12,ROUND((M16+N16)/2*IF(C16="I",Parametros!$B$9,IF(C16="II",Parametros!$B$10,Parametros!$B$11)),0))) -> 4 | P16: =IF(C16="I",Parametros!$B$14,IF(C16="II",Parametros!$B$15,Parametros!$B$16)) -> 3 | Q16: Laterita, que e o que o Brasil lavra. | R16: 0
A17: 13 | B17: Minerio de Silicio | C17: II | E17: Sim | F17: Roxo - Tecnologia | G17: Quartzo | H17: SiO2 | I17: Si | J17: 7 | K17: 2200 | L17: Silicio metalico | M17: =MIN(Parametros!$B$8,MAX(Parametros!$B$7,ROUND((LOG10(K17)-Parametros!$B$5)*Parametros!$B$6+1,0))) -> 3 | N17: =ROUND(J17,0) -> 7 | O17: =MIN(Parametros!$B$13,MAX(Parametros!$B$12,ROUND((M17+N17)/2*IF(C17="I",Parametros!$B$9,IF(C17="II",Parametros!$B$10,Parametros!$B$11)),0))) -> 5 | P17: =IF(C17="I",Parametros!$B$14,IF(C17="II",Parametros!$B$15,Parametros!$B$16)) -> 3 | R17: 0
A18: 14 | B18: Minerio de Tantalo | C18: II | E18: Sim | F18: Roxo - Tecnologia | G18: Columbita-tantalita | H18: (Fe,Mn)(Nb,Ta)2O6 | I18: Ta | J18: 6.25 | K18: 200000 | L18: Tantalo metalico | M18: =MIN(Parametros!$B$8,MAX(Parametros!$B$7,ROUND((LOG10(K18)-Parametros!$B$5)*Parametros!$B$6+1,0))) -> 6 | N18: =ROUND(J18,0) -> 6 | O18: =MIN(Parametros!$B$13,MAX(Parametros!$B$12,ROUND((M18+N18)/2*IF(C18="I",Parametros!$B$9,IF(C18="II",Parametros!$B$10,Parametros!$B$11)),0))) -> 6 | P18: =IF(C18="I",Parametros!$B$14,IF(C18="II",Parametros!$B$15,Parametros!$B$16)) -> 3 | R18: 0
A19: 15 | B19: Minerio de Terras Raras | C19: II | E19: Sim | F19: Roxo - Tecnologia | G19: Argila ionica | H19: (adsorcao ionica em argilominerais) | I19: ETR | J19: 1.5 | K19: 80000 | L19: Oxidos de terras raras | M19: =MIN(Parametros!$B$8,MAX(Parametros!$B$7,ROUND((LOG10(K19)-Parametros!$B$5)*Parametros!$B$6+1,0))) -> 5 | N19: =ROUND(J19,0) -> 2 | O19: =MIN(Parametros!$B$13,MAX(Parametros!$B$12,ROUND((M19+N19)/2*IF(C19="I",Parametros!$B$9,IF(C19="II",Parametros!$B$10,Parametros!$B$11)),0))) -> 4 | P19: =IF(C19="I",Parametros!$B$14,IF(C19="II",Parametros!$B$15,Parametros!$B$16)) -> 3 | Q19: Argila ionica, nao monazita: e a rota estrategica atual (Goias). | R19: 0
A20: 16 | B20: Minerio de Titanio | C20: II | E20: Sim | F20: Roxo - Tecnologia | G20: Ilmenita | H20: FeTiO3 | I20: Ti | J20: 5.5 | K20: 8000 | L20: Titanio esponja | M20: =MIN(Parametros!$B$8,MAX(Parametros!$B$7,ROUND((LOG10(K20)-Parametros!$B$5)*Parametros!$B$6+1,0))) -> 4 | N20: =ROUND(J20,0) -> 6 | O20: =MIN(Parametros!$B$13,MAX(Parametros!$B$12,ROUND((M20+N20)/2*IF(C20="I",Parametros!$B$9,IF(C20="II",Parametros!$B$10,Parametros!$B$11)),0))) -> 5 | P20: =IF(C20="I",Parametros!$B$14,IF(C20="II",Parametros!$B$15,Parametros!$B$16)) -> 3 | R20: 0
A21: 17 | B21: Minerio de Tungstenio | C21: II | E21: Sim | F21: Roxo - Tecnologia | G21: Scheelita | H21: CaWO4 | I21: W | J21: 4.75 | K21: 35000 | L21: Tungstenio (APT) | M21: =MIN(Parametros!$B$8,MAX(Parametros!$B$7,ROUND((LOG10(K21)-Parametros!$B$5)*Parametros!$B$6+1,0))) -> 5 | N21: =ROUND(J21,0) -> 5 | O21: =MIN(Parametros!$B$13,MAX(Parametros!$B$12,ROUND((M21+N21)/2*IF(C21="I",Parametros!$B$9,IF(C21="II",Parametros!$B$10,Parametros!$B$11)),0))) -> 5 | P21: =IF(C21="I",Parametros!$B$14,IF(C21="II",Parametros!$B$15,Parametros!$B$16)) -> 3 | Q21: Currais Novos (RN). | R21: 0
A22: 18 | B22: Minerio de Uranio | C22: II | D22: III | E22: Sim | F22: Roxo - Tecnologia | G22: Uraninita | H22: UO2 | I22: U | J22: 5.5 | K22: 176000 | L22: U3O8 | M22: =MIN(Parametros!$B$8,MAX(Parametros!$B$7,ROUND((LOG10(K22)-Parametros!$B$5)*Parametros!$B$6+1,0))) -> 6 | N22: =ROUND(J22,0) -> 6 | O22: =MIN(Parametros!$B$13,MAX(Parametros!$B$12,ROUND((M22+N22)/2*IF(C22="I",Parametros!$B$9,IF(C22="II",Parametros!$B$10,Parametros!$B$11)),0))) -> 6 | P22: =IF(C22="I",Parametros!$B$14,IF(C22="II",Parametros!$B$15,Parametros!$B$16)) -> 3 | Q22: Bloco duplo. Caetite (BA). | R22: 0
A23: 19 | B23: Minerio de Vanadio | C23: II | E23: Sim | F23: Roxo - Tecnologia | G23: Magnetita vanadifera | H23: (Fe,V)3O4 | I23: V | J23: 6 | K23: 9000 | L23: Pentoxido de vanadio | M23: =MIN(Parametros!$B$8,MAX(Parametros!$B$7,ROUND((LOG10(K23)-Parametros!$B$5)*Parametros!$B$6+1,0))) -> 4 | N23: =ROUND(J23,0) -> 6 | O23: =MIN(Parametros!$B$13,MAX(Parametros!$B$12,ROUND((M23+N23)/2*IF(C23="I",Parametros!$B$9,IF(C23="II",Parametros!$B$10,Parametros!$B$11)),0))) -> 5 | P23: =IF(C23="I",Parametros!$B$14,IF(C23="II",Parametros!$B$15,Parametros!$B$16)) -> 3 | Q23: Maracas (BA). | R23: 0
A24: 20 | B24: Minerio de Cromo | C24: II | E24: COMPLEMENTAR | F24: Roxo - Tecnologia | G24: Cromita | H24: FeCr2O4 | I24: Cr | J24: 5.5 | K24: 2000 | L24: Ferrocromo | M24: =MIN(Parametros!$B$8,MAX(Parametros!$B$7,ROUND((LOG10(K24)-Parametros!$B$5)*Parametros!$B$6+1,0))) -> 3 | N24: =ROUND(J24,0) -> 6 | O24: =MIN(Parametros!$B$13,MAX(Parametros!$B$12,ROUND((M24+N24)/2*IF(C24="I",Parametros!$B$9,IF(C24="II",Parametros!$B$10,Parametros!$B$11)),0))) -> 5 | P24: =IF(C24="I",Parametros!$B$14,IF(C24="II",Parametros!$B$15,Parametros!$B$16)) -> 3 | Q24: NAO consta na Resolucao 2/2021. Incluida para viabilizar o aco inoxidavel. Campo Formoso (BA). | R24: 0
A25: 21 | B25: Minerio de Zinco | C25: II | E25: COMPLEMENTAR | F25: Roxo - Tecnologia | G25: Esfalerita | H25: ZnS | I25: Zn | J25: 3.75 | K25: 2700 | L25: Zinco refinado | M25: =MIN(Parametros!$B$8,MAX(Parametros!$B$7,ROUND((LOG10(K25)-Parametros!$B$5)*Parametros!$B$6+1,0))) -> 3 | N25: =ROUND(J25,0) -> 4 | O25: =MIN(Parametros!$B$13,MAX(Parametros!$B$12,ROUND((M25+N25)/2*IF(C25="I",Parametros!$B$9,IF(C25="II",Parametros!$B$10,Parametros!$B$11)),0))) -> 4 | P25: =IF(C25="I",Parametros!$B$14,IF(C25="II",Parametros!$B$15,Parametros!$B$16)) -> 3 | Q25: NAO consta na Resolucao 2/2021. Incluida para viabilizar latao e galvanizacao. Vazante (MG). | R25: 0
A26: 22 | B26: Minerio de Aluminio | C26: III | E26: Sim | F26: Verde - Superavit | G26: Gibbsita (bauxita) | H26: Al(OH)3 | I26: Al | J26: 2.75 | K26: 2450 | L26: Aluminio primario | M26: =MIN(Parametros!$B$8,MAX(Parametros!$B$7,ROUND((LOG10(K26)-Parametros!$B$5)*Parametros!$B$6+1,0))) -> 3 | N26: =ROUND(J26,0) -> 3 | O26: =MIN(Parametros!$B$13,MAX(Parametros!$B$12,ROUND((M26+N26)/2*IF(C26="I",Parametros!$B$9,IF(C26="II",Parametros!$B$10,Parametros!$B$11)),0))) -> 2 | P26: =IF(C26="I",Parametros!$B$14,IF(C26="II",Parametros!$B$15,Parametros!$B$16)) -> 4 | R26: 0
A27: 23 | B27: Minerio de Ferro | C27: III | E27: Sim | F27: Verde - Superavit | G27: Hematita | H27: Fe2O3 | I27: Fe | J27: 6 | K27: 105 | L27: Minerio de ferro | M27: =MIN(Parametros!$B$8,MAX(Parametros!$B$7,ROUND((LOG10(K27)-Parametros!$B$5)*Parametros!$B$6+1,0))) -> 1 | N27: =ROUND(J27,0) -> 6 | O27: =MIN(Parametros!$B$13,MAX(Parametros!$B$12,ROUND((M27+N27)/2*IF(C27="I",Parametros!$B$9,IF(C27="II",Parametros!$B$10,Parametros!$B$11)),0))) -> 3 | P27: =IF(C27="I",Parametros!$B$14,IF(C27="II",Parametros!$B$15,Parametros!$B$16)) -> 4 | Q27: Parede barata: pouco ataque, muita defesa. | R27: 1
A28: 24 | B28: Minerio de Ouro | C28: III | E28: Sim | F28: Verde - Superavit | G28: Ouro nativo | H28: Au | I28: Au | J28: 2.75 | K28: 70000000 | L28: Ouro | M28: =MIN(Parametros!$B$8,MAX(Parametros!$B$7,ROUND((LOG10(K28)-Parametros!$B$5)*Parametros!$B$6+1,0))) -> 9 | N28: =ROUND(J28,0) -> 3 | O28: =MIN(Parametros!$B$13,MAX(Parametros!$B$12,ROUND((M28+N28)/2*IF(C28="I",Parametros!$B$9,IF(C28="II",Parametros!$B$10,Parametros!$B$11)),0))) -> 5 | P28: =IF(C28="I",Parametros!$B$14,IF(C28="II",Parametros!$B$15,Parametros!$B$16)) -> 4 | R28: 0
A29: 25 | B29: Minerio de Manganes | C29: III | E29: Sim | F29: Verde - Superavit | G29: Pirolusita | H29: MnO2 | I29: Mn | J29: 6.25 | K29: 320 | L29: Minerio de manganes | M29: =MIN(Parametros!$B$8,MAX(Parametros!$B$7,ROUND((LOG10(K29)-Parametros!$B$5)*Parametros!$B$6+1,0))) -> 2 | N29: =ROUND(J29,0) -> 6 | O29: =MIN(Parametros!$B$13,MAX(Parametros!$B$12,ROUND((M29+N29)/2*IF(C29="I",Parametros!$B$9,IF(C29="II",Parametros!$B$10,Parametros!$B$11)),0))) -> 3 | P29: =IF(C29="I",Parametros!$B$14,IF(C29="II",Parametros!$B$15,Parametros!$B$16)) -> 4 | R29: 0
B30: MEDIAS / TOTAL | M30: =ROUND(AVERAGE(M5:M29),2) -> 4.08 | N30: =ROUND(AVERAGE(N5:N29),2) -> 4.56 | O30: =ROUND(AVERAGE(O5:O29),2) -> 4.32 | P30: =SUM(P5:P29) -> 75 | R30: 0
B31: (medias de ataque/defesa/custo; total de cartas no pool) | R31: 0

Sheet Teste Vanilla
A1: Base do preco | B1: ATAQUE | C1: DEFESA | D1: CUSTO
A2: Enxofre bruto | B2: 1 | C2: 2 | D2: 2
A3: Concentrado fosfatico | B3: 2 | C3: 5 | D3: 4
A4: Cloreto de potassio (KCl) | B4: 2 | C4: 2 | D4: 2
A5: Molibdenio metalico | B5: 5 | C5: 1 | D5: 3
A6: Cobalto refinado | B6: 5 | C6: 3 | D6: 4
A7: Cobre refinado | B7: 4 | C7: 4 | D7: 4
A8: Estanho refinado | B8: 5 | C8: 7 | D8: 6
A9: Grafita natural em flocos | B9: 2 | C9: 2 | D9: 2
A10: Platina | B10: 9 | C10: 7 | D10: 8
A11: Carbonato de litio equiv. | B11: 4 | C11: 7 | D11: 6
A12: Ferronióbio | B12: 5 | C12: 5 | D12: 5
A13: Niquel refinado | B13: 4 | C13: 3 | D13: 4
... A26: Minerio de manganes | B26: 2 | C26: 6 | D26: 3

Sheet Curva de Mana
A1: Curva de custo - diagnostico
A2: Se amontoar num custo so, ajuste os multiplicadores na aba Parametros.
A4: Custo | B4: Cartas unicas | C4: Cartas no pool | D4: Alvo sugerido
A5: 1 | B5: =COUNTIF(Cartas!$O$5:$O$29,A5) -> 0 | C5: =SUMIF(Cartas!$O$5:$O$29,A5,Cartas!$O$5:$O$29) -> 0 | D5: 3
A6: 2 | B6: =COUNTIF(Cartas!$O$5:$O$29,A6) -> 4 | C6: =SUMIF(Cartas!$O$5:$O$29,A6,Cartas!$O$5:$O$29) -> 8 | D6: 4
A7: 3 | B7: =COUNTIF(Cartas!$O$5:$O$29,A7) -> 3 | C7: =SUMIF(Cartas!$O$5:$O$29,A7,Cartas!$O$5:$O$29) -> 9 | D7: 4
A8: 4 | B8: =COUNTIF(Cartas!$O$5:$O$29,A8) -> 6 | C8: =SUMIF(Cartas!$O$5:$O$29,A8,Cartas!$O$5:$O$29) -> 24 | D8: 4
A9: 5 | B9: =COUNTIF(Cartas!$O$5:$O$29,A9) -> 7 | C9: =SUMIF(Cartas!$O$5:$O$29,A9,Cartas!$O$5:$O$29) -> 35 | D9: 3
A10: 6 | B10: =COUNTIF(Cartas!$O$5:$O$29,A10) -> 4 | C10: =SUMIF(Cartas!$O$5:$O$29,A10,Cartas!$O$5:$O$29) -> 24 | D10: 3
A11: 7 | B11: =COUNTIF(Cartas!$O$5:$O$29,A11) -> 0 | C11: =SUMIF(Cartas!$O$5:$O$29,A11,Cartas!$O$5:$O$29) -> 0 | D11: 2
A12: 8 | B12: =COUNTIF(Cartas!$O$5:$O$29,A12) -> 1 | C12: =SUMIF(Cartas!$O$5:$O$29,A12,Cartas!$O$5:$O$29) -> 8 | D12: 1
A13: 9 | B13: =COUNTIF(Cartas!$O$5:$O$29,A13) -> 0 | C13: =SUMIF(Cartas!$O$5:$O$29,A13,Cartas!$O$5:$O$29) -> 0 | D13: 0
A14: Total | B14: =SUM(B5:B13) -> 25 | C14: =SUM(C5:C13) -> 108
A16: Cartas por bloco principal
A17: Bloco I | B17: =COUNTIF(Cartas!$C$5:$C$29,"I") -> 4 | C17: =SUMIF(Cartas!$C$5:$C$29,"I",Cartas!$P$5:$P$29) -> 8
A18: Bloco II | B18: =COUNTIF(Cartas!$C$5:$C$29,"II") -> 17 | C18: =SUMIF(Cartas!$C$5:$C$29,"II",Cartas!$P$5:$P$29) -> 51
A19: Bloco III | B19: =COUNTIF(Cartas!$C$5:$C$29,"III") -> 4 | C19: =SUMIF(Cartas!$C$5:$C$29,"III",Cartas!$P$5:$P$29) -> 16
A21: Cartas de bloco duplo (II e III) | B21: =COUNTIF(Cartas!$D$5:$D$29,"III") -> 4

Sheet Ligas (Combos)
A1: Ligas - a unica habilidade do jogo
A2: Com as cartas no seu campo, funda-as: viram uma carta so, com ataque e defesa somados, +2/+2.
A4: # | B4: Liga | C4: Cartas necessarias | D4: O que ensina
A5: 1 | B5: Aco | C5: Ferro + Grafita | D5: Fe + C: a liga base da industria.
A6: 2 | B6: Aco inoxidavel | C6: Ferro + Cromo + Niquel | D6: Fe + Cr + Ni: o cromo forma a camada passiva que impede a ferrugem.
A7: 3 | B7: Ferro-niobio | C7: Ferro + Niobio | D7: Fe + Nb: microliga de alta resistencia. A carta-simbolo do Brasil.
A8: 4 | B8: Ferrossilicio | C8: Ferro + Silicio | D8: Fe + Si: desoxidante siderurgico e aco eletrico.
A9: 5 | B9: Ferrovanadio | C9: Ferro + Vanadio | D9: Fe + V: aco HSLA, vergalhao e mola.
A10: 6 | B10: Aco rapido (HSS) | C10: Ferro + Tungstenio + Molibdenio | D10: Fe + W + Mo: mantem dureza em alta temperatura.
A11: 7 | B11: Galvanizacao | C11: Ferro + Zinco | D11: Fe + Zn: o zinco se corroi no lugar do aco - protecao catodica.
A12: 8 | B12: Bronze | C12: Cobre + Estanho | D12: Cu + Sn: a liga que nomeia uma era.
A13: 9 | B13: Latao | C13: Cobre + Zinco | D13: Cu + Zn: conexao eletrica e hidraulica.
A14: 10 | B14: Solda sem chumbo | C14: Estanho + Cobre | D14: Sn + Cu: eletronica moderna, apos a restricao ao chumbo.
A15: 11 | B15: Duraluminio | C15: Aluminio + Cobre | D15: Al + Cu: leveza estrutural, base da aeronautica.
A16: 12 | B16: Liga Ti-6Al-4V | C16: Titanio + Aluminio + Vanadio | D16: Ti + Al + V: implante e aeroespacial. As tres na lista oficial.
... A25: 21 | B25: Superfosfato | C25: Enxofre + Fosfato | D25: S + P: acido sulfurico ataca a rocha fosfatica.

Sheet Regras (v0.2)
A1: Regras - teste em papel
A3: Objetivo | B3: Zerar a RESERVA do adversario. Cada jogador comeca com 15.
A4: Energia | B4: A mana. Comeca em 1, sobe 1 por turno ate 9, recarrega cheia todo turno.
A5: Baralho | B5: Pool de 76 cartas. Cada jogador sorteia 15 no inicio.
A6: Mao inicial | B6: 3 cartas. Quem joga em segundo compra 4.
A7: Compra | B7: 1 por turno.
A8: Campo | B8: Maximo 3 minerais por jogador.
A9: Ataque | B9: Ataca outro mineral ou a reserva. Nao ataca no turno em que entra.
A10: Dano | B10: O ataque reduz a defesa do alvo. Defesa zerada, a carta sai.
A11: Ligas | B11: Cartas da liga no seu campo? Funda no seu turno: viram uma carta com ataque e defesa somados, +2/+2.
B12: A liga pode atacar no turno em que e formada.
A13: Duracao alvo | B13: 3 a 5 minutos.
A15: A TESTAR | B15: Passou de 5 min? Reserva 15 -> 12.
B16: Ninguem forma liga? Compra 2 por turno.
B17: Liga dominando? Tire o +2/+2 e deixe so a soma.
B18: Bloco I inutil? Suba as copias de 2 para 3.

Sheet Pendencias
A1: Decisoes em aberto
A3: # | B3: Questao | C3: Situacao / sugestao
A4: 1 | B4: Talio - REMOVIDO | C4: Estava na Resolucao, mas nao ha lavra de talio no Brasil (so subproduto de torrefacao de sulfetos). Retirado do baralho por decisao de projeto. Se algum revisor cobrar, a justificativa e ausencia de mineral de referencia brasileiro.
A5: 2 | B5: Cromo e zinco - ADICIONADOS fora da lista | C5: Nao constam na Resolucao 2/2021. Incluidos para viabilizar aco inox, latao, galvanizacao e solda. Marcados como COMPLEMENTAR na coluna E - manter essa marcacao em qualquer publicacao.
A6: 3 | B6: Bloco duplo (cobre, grafita, niobio, uranio) | C6: Adotei: bloco principal = II (tecnologia), com selo de superavit na coluna D. Se preferir o inverso, e so trocar as colunas C e D.
A7: 4 | B7: Precos sao ilustrativos | C7: Trocar por ANM (Anuario Mineral Brasileiro) e USGS antes de qualquer publicacao.
A8: 5 | B8: Base de preco mistura minerio e metal | C8: Segui a logica dos proprios blocos: Bloco II usa metal refinado (aplicacao tecnologica), Bloco III usa minerio (balanca comercial). Declarado linha a linha na coluna K.
A9: 6 | B9: Cobalto e subproduto | C9: Referencia trocada de cobaltita para asbolana da zona limonitica da laterita niquelifera - que e a fase portadora real no Brasil. Isso derruba a defesa de 6 para 3: carta cara e fragil, coerente com nao existir mina propria.
A10: 7 | B10: Terras raras | C10: Argila ionica como referencia (Mohs ~1,5), nao monazita. Da defesa 2 - a carta mais fragil e uma das mais caras.
A11: 8 | B11: So 24 cartas unicas | C11: Com baralho de 15, as partidas variam pouco. Se ficar repetitivo, reduza o baralho para 12 ou aumente as copias assimetricamente.
